{"metadata":{"kernelspec":{"display_name":"Python 3 (ipykernel)","language":"python","name":"python3"},"language_info":{"name":"python","version":"3.10.11","mimetype":"text/x-python","codemirror_mode":{"name":"ipython","version":3},"pygments_lexer":"ipython3","nbconvert_exporter":"python","file_extension":".py"}},"nbformat_minor":4,"nbformat":4,"cells":[{"cell_type":"markdown","source":"# Dealing with errors\n\nFinnish university students are encouraged to use the CSC Notebooks platform.<br/>\n<a href=\"https://notebooks.csc.fi/\"><img alt=\"CSC badge\" src=\"https://img.shields.io/badge/launch-CSC%20notebook-blue.svg\" style=\"vertical-align:text-bottom\"></a>\n\nOthers can follow the lesson and fill in their student notebooks using Binder.<br/>\n<a href=\"https://mybinder.org/v2/gh/geo-python/notebooks/master?urlpath=lab/tree/L6/errors.ipynb\"><img alt=\"Binder badge\" src=\"https://img.shields.io/badge/launch-binder-red.svg\" style=\"vertical-align:text-bottom\"></a>\n\n## Interpreting error messages\n\nSo far in the course we have encountered a number of different types of error messages in Python, but have not really discussed how to understand what the computer is trying to tell you when you get an error message.\nWe'll do that below.\nFor most Python errors you will see and exception raised when the error is encountered, providing some insight into what went wrong and where to look to fix it.","metadata":{"tags":["raises-exception"]}},{"cell_type":"markdown","source":"### Reading error messages\n\nLet's imagine you've written the code below called to convert wind speeds from km/hr to m/s and you're dying to figure out how windy it is in [Halifax, Nova Scotia, Canada](https://www.theweathernetwork.com/ca/weather/nova-scotia/halifax) where they report wind speeds in km/hr.\n\nUnfortunately, when you run your script you observe the following:","metadata":{}},{"cell_type":"code","source":"wind_speed_km = 50\nwind_speed_ms = wind_speed_km * 1000 / 3600\n\nprint(f\"A wind speed of {wind_speed_km} km/hr is {wind_speed_ms} m/s.)","metadata":{"tags":["raises-exception"],"trusted":true},"execution_count":1,"outputs":[{"traceback":["\u001b[0;36m  Cell \u001b[0;32mIn[1], line 4\u001b[0;36m\u001b[0m\n\u001b[0;31m    print(f\"A wind speed of {wind_speed_km} km/hr is {wind_speed_ms} m/s.)\u001b[0m\n\u001b[0m          ^\u001b[0m\n\u001b[0;31mSyntaxError\u001b[0m\u001b[0;31m:\u001b[0m unterminated string literal (detected at line 4)\n"],"ename":"SyntaxError","evalue":"unterminated string literal (detected at line 4) (2231829726.py, line 4)","output_type":"error"}]},{"cell_type":"markdown","source":"Let's break this example down and see what the error message says.\n\n![Syntax error](img/error-message-annotated.png)\n*A SyntaxError, annotated*\n\nAs you can see, there is quite a bit of useful information here. We have some information about the code cell that was run, as well as which line of the cell was a problem. We also have the type of error, a `SyntaxError` in this case, where it occurred on the line, and a bit more information about its meaning. The location on the line won't always be correct, but Python makes its best guess for where you should look to solve the problem. In this case, we can see that our f-string is missing the second set of quotation marks.\n\nLet's consider another example, where you have fixed the `SyntaxError` above and now have made a function for calculating a wind speeds in m/s.\n\nWhen you run this script you encounter a new and bigger error message:","metadata":{}},{"cell_type":"code","source":"def convert_wind_speed(speed):\n    return speed * 1000 / 3600\n\nwind_speed_km = '30'\nwind_speed_ms = convert_wind_speed(wind_speed_km)\n\nprint(f\"A wind speed of {wind_speed_km} km/hr is {wind_speed_ms} m/s.\")","metadata":{"tags":["raises-exception"],"trusted":true},"execution_count":2,"outputs":[{"traceback":["\u001b[0;31m---------------------------------------------------------------------------\u001b[0m","\u001b[0;31mTypeError\u001b[0m                                 Traceback (most recent call last)","Cell \u001b[0;32mIn[2], line 5\u001b[0m\n\u001b[1;32m      2\u001b[0m     \u001b[38;5;28;01mreturn\u001b[39;00m speed \u001b[38;5;241m*\u001b[39m \u001b[38;5;241m1000\u001b[39m \u001b[38;5;241m/\u001b[39m \u001b[38;5;241m3600\u001b[39m\n\u001b[1;32m      4\u001b[0m wind_speed_km \u001b[38;5;241m=\u001b[39m \u001b[38;5;124m'\u001b[39m\u001b[38;5;124m30\u001b[39m\u001b[38;5;124m'\u001b[39m\n\u001b[0;32m----> 5\u001b[0m wind_speed_ms \u001b[38;5;241m=\u001b[39m \u001b[43mconvert_wind_speed\u001b[49m\u001b[43m(\u001b[49m\u001b[43mwind_speed_km\u001b[49m\u001b[43m)\u001b[49m\n\u001b[1;32m      7\u001b[0m \u001b[38;5;28mprint\u001b[39m(\u001b[38;5;124mf\u001b[39m\u001b[38;5;124m\"\u001b[39m\u001b[38;5;124mA wind speed of \u001b[39m\u001b[38;5;132;01m{\u001b[39;00mwind_speed_km\u001b[38;5;132;01m}\u001b[39;00m\u001b[38;5;124m km/hr is \u001b[39m\u001b[38;5;132;01m{\u001b[39;00mwind_speed_ms\u001b[38;5;132;01m}\u001b[39;00m\u001b[38;5;124m m/s.\u001b[39m\u001b[38;5;124m\"\u001b[39m)\n","Cell \u001b[0;32mIn[2], line 2\u001b[0m, in \u001b[0;36mconvert_wind_speed\u001b[0;34m(speed)\u001b[0m\n\u001b[1;32m      1\u001b[0m \u001b[38;5;28;01mdef\u001b[39;00m \u001b[38;5;21mconvert_wind_speed\u001b[39m(speed):\n\u001b[0;32m----> 2\u001b[0m     \u001b[38;5;28;01mreturn\u001b[39;00m \u001b[43mspeed\u001b[49m\u001b[43m \u001b[49m\u001b[38;5;241;43m*\u001b[39;49m\u001b[43m \u001b[49m\u001b[38;5;241;43m1000\u001b[39;49m\u001b[43m \u001b[49m\u001b[38;5;241;43m/\u001b[39;49m\u001b[43m \u001b[49m\u001b[38;5;241;43m3600\u001b[39;49m\n","\u001b[0;31mTypeError\u001b[0m: unsupported operand type(s) for /: 'str' and 'int'"],"ename":"TypeError","evalue":"unsupported operand type(s) for /: 'str' and 'int'","output_type":"error"}]},{"cell_type":"markdown","source":"In this case we see a `TypeError` that is part of a *traceback*, where the problem in the code arises from something other than on the line where the code was run. In this case, we have a `TypeError` where we try to divide a character string by a number, something Python cannot do. Hence, the `TypeError` indicating the data types are not compatible. That error, however, does not occur when the code is run until the point where the function is used. Thus, we see the traceback showing that not only does the error occur when the function is called, but also that the problem is in the function definition (note the two arrows indicating the problem lines).\n\nThe traceback above may look a bit scarier, but if you take your time and read through what is output, you will again find that the information is helpful in finding the problem in your code. After all, the purpose of the error message is to help the user find a problem :).\n\n#### Error messages in Python 3.10 and newer\n\nOur course environment is using Python 3.10 which was released in October 2021. Among the changes in this release are [improvements in the error messages](https://docs.python.org/3.10/whatsnew/3.10.html#better-error-messages) that are generated for many of the cases below. Nice!","metadata":{}},{"cell_type":"markdown","source":"### Common errors and exceptions\n\nNow that we have some idea of how to read an error message, let's have a look at a few different types of common Python exceptions that are displayed for different program errors.\n\n#### IndexErrors\n\nAn `IndexError` occurs when you attempt to reference a value with an index outside the range of values.\nWe can easily produce an `IndexError` by trying to access the value at index 5 in the following list of cities: `cities = ['Paris', 'Berlin', 'London']`.","metadata":{}},{"cell_type":"code","source":"cities = [\"Paris\", \"Berlin\", \"London\"]","metadata":{"trusted":true,"tags":[]},"execution_count":3,"outputs":[]},{"cell_type":"code","source":"cities[5]","metadata":{"tags":["raises-exception"],"trusted":true},"execution_count":4,"outputs":[{"traceback":["\u001b[0;31m---------------------------------------------------------------------------\u001b[0m","\u001b[0;31mIndexError\u001b[0m                                Traceback (most recent call last)","Cell \u001b[0;32mIn[4], line 1\u001b[0m\n\u001b[0;32m----> 1\u001b[0m \u001b[43mcities\u001b[49m\u001b[43m[\u001b[49m\u001b[38;5;241;43m5\u001b[39;49m\u001b[43m]\u001b[49m\n","\u001b[0;31mIndexError\u001b[0m: list index out of range"],"ename":"IndexError","evalue":"list index out of range","output_type":"error"}]},{"cell_type":"markdown","source":"Here we get the rather clear error message that the index used for the list `cities` is outside of the range of index values for that list.","metadata":{}},{"cell_type":"markdown","source":"#### NameErrors\n\nA `NameError` typically occurs when you reference a variable that has not been defined. We can produce a `NameError` by trying `station_id = stations[1]`.","metadata":{}},{"cell_type":"code","source":"station_id = stations[1]","metadata":{"tags":["raises-exception"],"trusted":true},"execution_count":5,"outputs":[{"traceback":["\u001b[0;31m---------------------------------------------------------------------------\u001b[0m","\u001b[0;31mNameError\u001b[0m                                 Traceback (most recent call last)","Cell \u001b[0;32mIn[5], line 1\u001b[0m\n\u001b[0;32m----> 1\u001b[0m station_id \u001b[38;5;241m=\u001b[39m \u001b[43mstations\u001b[49m[\u001b[38;5;241m1\u001b[39m]\n","\u001b[0;31mNameError\u001b[0m: name 'stations' is not defined"],"ename":"NameError","evalue":"name 'stations' is not defined","output_type":"error"}]},{"cell_type":"markdown","source":"In this instance we receive a `NameError` because the list `stations` has not been defined, and we're thus not able to access a value in that list.","metadata":{}},{"cell_type":"markdown","source":"#### IndentationErrors\n\nAn `IndentationError` is raised whenever a code block is expected to be indented and is either (1) not indented, or (2) is indented inconsistently. Let's see this in two examples below.","metadata":{}},{"cell_type":"code","source":"for city in cities:\n    city = city + \" is a city in Europe\"\n  print(city)","metadata":{"tags":["raises-exception"],"trusted":true},"execution_count":7,"outputs":[{"traceback":["\u001b[0;36m  File \u001b[0;32m<tokenize>:3\u001b[0;36m\u001b[0m\n\u001b[0;31m    print(city)\u001b[0m\n\u001b[0m    ^\u001b[0m\n\u001b[0;31mIndentationError\u001b[0m\u001b[0;31m:\u001b[0m unindent does not match any outer indentation level\n"],"ename":"IndentationError","evalue":"unindent does not match any outer indentation level (<tokenize>, line 3)","output_type":"error"}]},{"cell_type":"code","source":"for city in cities:\ncity = city + \" is a city in Europe\"\nprint(city)","metadata":{"tags":["raises-exception"],"trusted":true},"execution_count":8,"outputs":[{"traceback":["\u001b[0;36m  Cell \u001b[0;32mIn[8], line 2\u001b[0;36m\u001b[0m\n\u001b[0;31m    city = city + \" is a city in Europe\"\u001b[0m\n\u001b[0m    ^\u001b[0m\n\u001b[0;31mIndentationError\u001b[0m\u001b[0;31m:\u001b[0m expected an indented block after 'for' statement on line 1\n"],"ename":"IndentationError","evalue":"expected an indented block after 'for' statement on line 1 (1297196788.py, line 2)","output_type":"error"}]},{"cell_type":"markdown","source":"In both of the examples above, an `IndentationError` is raised. In the first case, the indentation level is inconsistent. In case two, indentation is expected for the code below a `for` statement.","metadata":{}},{"cell_type":"markdown","source":"#### TypeErrors\n\nA `TypeError` is raised whenever two incompatible data types are used together. For example, if we try to divide a character string by a number or add a number to a boolean variable, a `TypeError` will be raised.","metadata":{}},{"cell_type":"code","source":"cities[0] / 5","metadata":{"tags":["raises-exception"],"trusted":true},"execution_count":9,"outputs":[{"traceback":["\u001b[0;31m---------------------------------------------------------------------------\u001b[0m","\u001b[0;31mTypeError\u001b[0m                                 Traceback (most recent call last)","Cell \u001b[0;32mIn[9], line 1\u001b[0m\n\u001b[0;32m----> 1\u001b[0m \u001b[43mcities\u001b[49m\u001b[43m[\u001b[49m\u001b[38;5;241;43m0\u001b[39;49m\u001b[43m]\u001b[49m\u001b[43m \u001b[49m\u001b[38;5;241;43m/\u001b[39;49m\u001b[43m \u001b[49m\u001b[38;5;241;43m5\u001b[39;49m\n","\u001b[0;31mTypeError\u001b[0m: unsupported operand type(s) for /: 'str' and 'int'"],"ename":"TypeError","evalue":"unsupported operand type(s) for /: 'str' and 'int'","output_type":"error"}]},{"cell_type":"markdown","source":"In this case, the `TypeError` is because it is not possible to divide a character string by a number.","metadata":{}},{"cell_type":"markdown","source":"#### Other kinds of errors\n\nThere are certainly [other kinds of errors and exceptions in Python](https://docs.python.org/3/tutorial/errors.html), but this list comprises those you're most likely to encounter.\nAs you can see, knowing the name of each error can be helpful in trying to figure out what has gone wrong, and knowing what these common error types mean will save you time trying to fix your programs.","metadata":{}},{"cell_type":"markdown","source":"### More information on errors\n\nYou can find a bit more information about reading error messages on the [Software Carpentry](https://swcarpentry.github.io/python-novice-inflammation/09-errors.html) and [Python Software Foundation](https://docs.python.org/3/tutorial/errors.html) webpages.","metadata":{}}]}